Workbook

Sheet Shopping list
A1: Parts to buy: HastaDAQ main board + gauge board, rev A
A2: How to use: pick a Status in column A (dropdown), type what you bought in 'Qty bought' and the unit price; everything marked yellow is yours to fill in.
A3: Qty per board comes from the 'Board BOM' sheet; 'Qty needed' = main x boards + gauge x boards + other. Change the two board counts below (blue). | E3: Progress
A4: Status 'Own stock' counts as done. Supplier part numbers are RS stock numbers where they are known (from docs/PARTS_TO_SELECT.md); blank means not found yet. | B4: Main boards to populate | C4: 2 | E4: Items to buy | F4: =COUNTIF($A$12:$A$62,"Not ordered")+COUNTIF($A$12:$A$62,"Ordered")+COUNTIF($A$12:$A$62,"Received")+COUNTIF($A$12:$A$62,"Own stock") -> 43
B5: Gauge boards to populate | C5: 2 | E5: Not ordered | F5: =COUNTIF($A$12:$A$62,"Not ordered") -> 43
E6: Ordered, not yet received | F6: =COUNTIF($A$12:$A$62,"Ordered") -> 0
E7: Received or own stock | F7: =COUNTIF($A$12:$A$62,"Received")+COUNTIF($A$12:$A$62,"Own stock") -> 0
E8: Complete | F8: =IF(F4=0,0,F7/F4) -> 0
E9: Total spent (GBP) | F9: =SUM(N12:N62) -> 349.47
A11: Status | B11: Group | C11: Item | D11: Spec / value | E11: Supplier | F11: Supplier part no. (RS stock no.) | G11: Qty per main board | H11: Qty per gauge board | I11: Other qty (off-board / assembly) | J11: Qty needed | K11: Qty bought | L11: Still to buy | M11: Unit price (GBP) | N11: Line cost (GBP) | O11: Order ref / date | P11: Used on | Q11: Notes
B12: Main board modules
A13: Not ordered | B13: Main board modules | C13: Pimoroni Pico Plus 2 | D13: RP2350, 16 MB flash, 8 MB PSRAM, USB-C | E13: Pimoroni | G13: =SUMIFS('Board BOM'!$C$5:$C$53,'Board BOM'!$A$5:$A$53,"Main",'Board BOM'!$G$5:$G$53,$C13,'Board BOM'!$F$5:$F$53,"Yes") -> 1 | H13: =SUMIFS('Board BOM'!$C$5:$C$53,'Board BOM'!$A$5:$A$53,"Gauge",'Board BOM'!$G$5:$G$53,$C13,'Board BOM'!$F$5:$F$53,"Yes") -> 0 | J13: =G13*$C$4+H13*$C$5+I13 -> 2 | K13: 2 | L13: =MAX(J13-K13,0) -> 0 | N13: =K13*M13 -> 0 | P13: Main U1 | Q13: Footprint is the 'header pins' version: check the one you buy has headers (or add 2 x 1x20 pin headers). Soldered straight to the PCB.
A14: Not ordered | B14: Main board modules | C14: Pololu D42V55F8 step-down regulator | D14: 8.4 V, 5 A (servo rail), 6.1 mm tall | E14: ThePiHut | F14: COM-21256 | G14: =SUMIFS('Board BOM'!$C$5:$C$53,'Board BOM'!$A$5:$A$53,"Main",'Board BOM'!$G$5:$G$53,$C14,'Board BOM'!$F$5:$F$53,"Yes") -> 1 | H14: =SUMIFS('Board BOM'!$C$5:$C$53,'Board BOM'!$A$5:$A$53,"Gauge",'Board BOM'!$G$5:$G$53,$C14,'Board BOM'!$F$5:$F$53,"Yes") -> 0 | J14: =G14*$C$4+H14*$C$5+I14 -> 2 | K14: 2 | L14: =MAX(J14-K14,0) -> 0 | M14: 46.1 | N14: =K14*M14 -> 92.2 | P14: Main U2
A15: Not ordered | B15: Main board modules | C15: SparkFun BabyBuck 5V (AP63357) | D15: 5 V buck for Pico VSYS and Orbis | E15: ThePiHut | F15: COM-21256 | G15: =SUMIFS('Board BOM'!$C$5:$C$53,'Board BOM'!$A$5:$A$53,"Main",'Board BOM'!$G$5:$G$53,$C15,'Board BOM'!$F$5:$F$53,"Yes") -> 1 | H15: =SUMIFS('Board BOM'!$C$5:$C$53,'Board BOM'!$A$5:$A$53,"Gauge",'Board BOM'!$G$5:$G$53,$C15,'Board BOM'!$F$5:$F$53,"Yes") -> 0 | J15: =G15*$C$4+H15*$C$5+I15 -> 2 | K15: 3 | L15: =MAX(J15-K15,0) -> 0 | M15: 5.8 | N15: =K15*M15 -> 17.4 | P15: Main U3 | Q15: EN may be left open.
B16: Main board semiconductors
A17: Not ordered | B17: Main board semiconductors | C17: onsemi FOD817A opto-coupler | D17: 4-pin DIP, CTR 80-160 % | E17: RS Components | F17: 761-4439 | G17: =SUMIFS('Board BOM'!$C$5:$C$53,'Board BOM'!$A$5:$A$53,"Main",'Board BOM'!$G$5:$G$53,$C17,'Board BOM'!$F$5:$F$53,"Yes") -> 1 | H17: =SUMIFS('Board BOM'!$C$5:$C$53,'Board BOM'!$A$5:$A$53,"Gauge",'Board BOM'!$G$5:$G$53,$C17,'Board BOM'!$F$5:$F$53,"Yes") -> 0 | J17: =G17*$C$4+H17*$C$5+I17 -> 2 | K17: 10 | L17: =MAX(J17-K17,0) -> 0 | M17: 0.203 | N17: =K17*M17 -> 2.03 | P17: Main U4 | Q17: TRIG_IN stage.
A18: Not ordered | B18: Main board semiconductors | C18: 2N3904 NPN transistor | D18: TO-92 (pin 1 E, 2 B, 3 C) | E18: RS Components | F18: 843-1575 | G18: =SUMIFS('Board BOM'!$C$5:$C$53,'Board BOM'!$A$5:$A$53,"Main",'Board BOM'!$G$5:$G$53,$C18,'Board BOM'!$F$5:$F$53,"Yes") -> 1 | H18: =SUMIFS('Board BOM'!$C$5:$C$53,'Board BOM'!$A$5:$A$53,"Gauge",'Board BOM'!$G$5:$G$53,$C18,'Board BOM'!$F$5:$F$53,"Yes") -> 0 | J18: =G18*$C$4+H18*$C$5+I18 -> 2 | K18: 50 | L18: =MAX(J18-K18,0) -> 0 | M18: 0.182 | N18: =K18*M18 -> 9.1 | P18: Main Q1 | Q18: RS number not recorded in the docs: add it when you find it.
A19: Not ordered | B19: Main board semiconductors | C19: STMicroelectronics 1N5822 Schottky diode | D19: 3 A, 40 V, DO-201AD | E19: RS Components | F19: 687-0877 | G19: =SUMIFS('Board BOM'!$C$5:$C$53,'Board BOM'!$A$5:$A$53,"Main",'Board BOM'!$G$5:$G$53,$C19,'Board BOM'!$F$5:$F$53,"Yes") -> 1 | H19: =SUMIFS('Board BOM'!$C$5:$C$53,'Board BOM'!$A$5:$A$53,"Gauge",'Board BOM'!$G$5:$G$53,$C19,'Board BOM'!$F$5:$F$53,"Yes") -> 0 | J19: =G19*$C$4+H19*$C$5+I19 -> 2 | K19: 100 | L19: =MAX(J19-K19,0) -> 0 | M19: 0.109 | N19: =K19*M19 -> 10.9 | P19: Main D1 | Q19: Supply reverse-protection diode.
A20: Not ordered | B20: Main board semiconductors | C20: Taiwan Semi BZX55C5V1 zener diode | D20: 5.1 V, 500 mW, DO-35 | E20: RS Components | F20: 748-5051 | G20: =SUMIFS('Board BOM'!$C$5:$C$53,'Board BOM'!$A$5:$A$53,"Main",'Board BOM'!$G$5:$G$53,$C20,'Board BOM'!$F$5:$F$53,"Yes") -> 2 | H20: =SUMIFS('Board BOM'!$C$5:$C$53,'Board BOM'!$A$5:$A$53,"Gauge",'Board BOM'!$G$5:$G$53,$C20,'Board BOM'!$F$5:$F$53,"Yes") -> 0 | J20: =G20*$C$4+H20*$C$5+I20 -> 4 | K20: 200 | L20: =MAX(J20-K20,0) -> 0 | M20: 0.05 | N20: =K20*M20 -> 10 | P20: Main D2; Main D4 | Q20: D2 soft-stop clamp, D4 SBUS IN clamp.
A21: Not ordered | B21: Main board semiconductors | C21: Vishay BAV17-BAV21 switching diode | D21: DO-35, 250 mA (any family member) | E21: RS Components | F21: 700-3863 | G21: =SUMIFS('Board BOM'!$C$5:$C$53,'Board BOM'!$A$5:$A$53,"Main",'Board BOM'!$G$5:$G$53,$C21,'Board BOM'!$F$5:$F$53,"Yes") -> 1 | H21: =SUMIFS('Board BOM'!$C$5:$C$53,'Board BOM'!$A$5:$A$53,"Gauge",'Board BOM'!$G$5:$G$53,$C21,'Board BOM'!$F$5:$F$53,"Yes") -> 0 | J21: =G21*$C$4+H21*$C$5+I21 -> 2 | K21: 100 | L21: =MAX(J21-K21,0) -> 0 | M21: 0.06 | N21: =K21*M21 -> 6 | P21: Main D3 | Q21: Schematic text says 1N4148; any DO-35 small-signal diode works (1N4148 etc.). Confirm the exact type on the RS page.
B22: Main board capacitors
A23: Not ordered | B23: Main board capacitors | C23: Panasonic ECA1EM101 electrolytic 100 uF 25 V | D23: 6.3 x 11.2 mm, 2.5 mm pitch, 85 C | E23: RS Components | F23: 181-5448 | G23: =SUMIFS('Board BOM'!$C$5:$C$53,'Board BOM'!$A$5:$A$53,"Main",'Board BOM'!$G$5:$G$53,$C23,'Board BOM'!$F$5:$F$53,"Yes") -> 1 | H23: =SUMIFS('Board BOM'!$C$5:$C$53,'Board BOM'!$A$5:$A$53,"Gauge",'Board BOM'!$G$5:$G$53,$C23,'Board BOM'!$F$5:$F$53,"Yes") -> 0 | J23: =G23*$C$4+H23*$C$5+I23 -> 2 | K23: 100 | L23: =MAX(J23-K23,0) -> 0 | M23: 0.065 | N23: =K23*M23 -> 6.5 | P23: Main C1 | Q23: C1, 12 V input bulk.
A24: Not ordered | B24: Main board capacitors | C24: Panasonic EEUFR1C471 electrolytic 470 uF 16 V | D24: 8.0 x 11.5 mm, 3.5 mm pitch, low ESR, 105 C | E24: RS Components | F24: 708-3620 | G24: =SUMIFS('Board BOM'!$C$5:$C$53,'Board BOM'!$A$5:$A$53,"Main",'Board BOM'!$G$5:$G$53,$C24,'Board BOM'!$F$5:$F$53,"Yes") -> 1 | H24: =SUMIFS('Board BOM'!$C$5:$C$53,'Board BOM'!$A$5:$A$53,"Gauge",'Board BOM'!$G$5:$G$53,$C24,'Board BOM'!$F$5:$F$53,"Yes") -> 0 | J24: =G24*$C$4+H24*$C$5+I24 -> 2 | K24: 10 | L24: =MAX(J24-K24,0) -> 0 | M24: 0.298 | N24: =K24*M24 -> 2.98 | P24: Main C2 | Q24: C2, servo rail bulk.
A25: Not ordered | B25: Main board capacitors | C25: RS PRO LHK electrolytic 100 uF 10 V | D25: 5 x 7 mm, 2.0 mm pitch, 105 C | E25: RS Components | F25: 707-5799 | G25: =SUMIFS('Board BOM'!$C$5:$C$53,'Board BOM'!$A$5:$A$53,"Main",'Board BOM'!$G$5:$G$53,$C25,'Board BOM'!$F$5:$F$53,"Yes") -> 1 | H25: =SUMIFS('Board BOM'!$C$5:$C$53,'Board BOM'!$A$5:$A$53,"Gauge",'Board BOM'!$G$5:$G$53,$C25,'Board BOM'!$F$5:$F$53,"Yes") -> 0 | J25: =G25*$C$4+H25*$C$5+I25 -> 2 | K25: 200 | L25: =MAX(J25-K25,0) -> 0 | M25: 0.057 | N25: =K25*M25 -> 11.4 | P25: Main C3 | Q25: C3, 5 V bulk near the Pico.
B26: Resistors (1/4 W axial, DIN0207)
A27: Not ordered | B27: Resistors (1/4 W axial, DIN0207) | C27: Resistor 10 k | D27: 1/4 W axial | E27: RS Components | F27: 199-7658 | G27: =SUMIFS('Board BOM'!$C$5:$C$53,'Board BOM'!$A$5:$A$53,"Main",'Board BOM'!$G$5:$G$53,$C27,'Board BOM'!$F$5:$F$53,"Yes") -> 10 | H27: =SUMIFS('Board BOM'!$C$5:$C$53,'Board BOM'!$A$5:$A$53,"Gauge",'Board BOM'!$G$5:$G$53,$C27,'Board BOM'!$F$5:$F$53,"Yes") -> 0 | J27: =G27*$C$4+H27*$C$5+I27 -> 20 | K27: 100 | L27: =MAX(J27-K27,0) -> 0 | M27: 0.018 | N27: =K27*M27 -> 1.8 | P27: Main R1,R2,R3,R4,R15; Main R6; Main R7; Main R9; Main R11; Main R14 | Q27: Main R14 is left unfitted at first (SBUS IN pull-down) but included here.
A28: Not ordered | B28: Resistors (1/4 W axial, DIN0207) | C28: Resistor 1 k | D28: 1/4 W axial | E28: RS Components | F28: 199-7601 | G28: =SUMIFS('Board BOM'!$C$5:$C$53,'Board BOM'!$A$5:$A$53,"Main",'Board BOM'!$G$5:$G$53,$C28,'Board BOM'!$F$5:$F$53,"Yes") -> 2 | H28: =SUMIFS('Board BOM'!$C$5:$C$53,'Board BOM'!$A$5:$A$53,"Gauge",'Board BOM'!$G$5:$G$53,$C28,'Board BOM'!$F$5:$F$53,"Yes") -> 0 | J28: =G28*$C$4+H28*$C$5+I28 -> 4 | K28: 100 | L28: =MAX(J28-K28,0) -> 0 | M28: 0.018 | N28: =K28*M28 -> 1.8 | P28: Main R5; Main R13
A29: Not ordered | B29: Resistors (1/4 W axial, DIN0207) | C29: Resistor 2.2 k | D29: 1/4 W axial | E29: RS Components | F29: 199-7660 | G29: =SUMIFS('Board BOM'!$C$5:$C$53,'Board BOM'!$A$5:$A$53,"Main",'Board BOM'!$G$5:$G$53,$C29,'Board BOM'!$F$5:$F$53,"Yes") -> 1 | H29: =SUMIFS('Board BOM'!$C$5:$C$53,'Board BOM'!$A$5:$A$53,"Gauge",'Board BOM'!$G$5:$G$53,$C29,'Board BOM'!$F$5:$F$53,"Yes") -> 0 | J29: =G29*$C$4+H29*$C$5+I29 -> 2 | K29: 100 | L29: =MAX(J29-K29,0) -> 0 | M29: 0.018 | N29: =K29*M29 -> 1.8 | P29: Main R10 | Q29: Q1 base resistor.
A30: Not ordered | B30: Resistors (1/4 W axial, DIN0207) | C30: Resistor 1.5 k | D30: 1/4 W axial | E30: RS Components | F30: 199-7606 | G30: =SUMIFS('Board BOM'!$C$5:$C$53,'Board BOM'!$A$5:$A$53,"Main",'Board BOM'!$G$5:$G$53,$C30,'Board BOM'!$F$5:$F$53,"Yes") -> 1 | H30: =SUMIFS('Board BOM'!$C$5:$C$53,'Board BOM'!$A$5:$A$53,"Gauge",'Board BOM'!$G$5:$G$53,$C30,'Board BOM'!$F$5:$F$53,"Yes") -> 0 | J30: =G30*$C$4+H30*$C$5+I30 -> 2 | K30: 100 | L30: =MAX(J30-K30,0) -> 0 | M30: 0.018 | N30: =K30*M30 -> 1.8 | P30: Main R12 | Q30: TRIG_OUT pull-up.
A31: Not ordered | B31: Resistors (1/4 W axial, DIN0207) | C31: Resistor 1 k, 1 W | D31: 1 W axial, body about 9.9 x 3.6 mm | E31: RS Components | F31: 707-8669 | G31: =SUMIFS('Board BOM'!$C$5:$C$53,'Board BOM'!$A$5:$A$53,"Main",'Board BOM'!$G$5:$G$53,$C31,'Board BOM'!$F$5:$F$53,"Yes") -> 1 | H31: =SUMIFS('Board BOM'!$C$5:$C$53,'Board BOM'!$A$5:$A$53,"Gauge",'Board BOM'!$G$5:$G$53,$C31,'Board BOM'!$F$5:$F$53,"Yes") -> 0 | J31: =G31*$C$4+H31*$C$5+I31 -> 2 | K31: 10 | L31: =MAX(J31-K31,0) -> 0 | M31: 0.218 | N31: =K31*M31 -> 2.18 | P31: Main R8 | Q31: R8: 1 W because a 24 V trigger gives about 0.6 W.
A32: Not ordered | B32: Resistors (1/4 W axial, DIN0207) | C32: Resistor 0 ohm link | D32: 1/4 W axial | E32: RS Components | G32: =SUMIFS('Board BOM'!$C$5:$C$53,'Board BOM'!$A$5:$A$53,"Main",'Board BOM'!$G$5:$G$53,$C32,'Board BOM'!$F$5:$F$53,"Yes") -> 0 | H32: =SUMIFS('Board BOM'!$C$5:$C$53,'Board BOM'!$A$5:$A$53,"Gauge",'Board BOM'!$G$5:$G$53,$C32,'Board BOM'!$F$5:$F$53,"Yes") -> 4 | J32: =G32*$C$4+H32*$C$5+I32 -> 8 | K32: 8 | L32: =MAX(J32-K32,0) -> 0 | M32: 0 | N32: =K32*M32 -> 0 | P32: Gauge R1,R2,R3,R4 | Q32: Gauge board input-filter positions.
A33: Not ordered | B33: Resistors (1/4 W axial, DIN0207) | C33: Resistor 350 ohm precision | D33: 1/4 W axial | E33: Own stock | G33: =SUMIFS('Board BOM'!$C$5:$C$53,'Board BOM'!$A$5:$A$53,"Main",'Board BOM'!$G$5:$G$53,$C33,'Board BOM'!$F$5:$F$53,"Yes") -> 0 | H33: =SUMIFS('Board BOM'!$C$5:$C$53,'Board BOM'!$A$5:$A$53,"Gauge",'Board BOM'!$G$5:$G$53,$C33,'Board BOM'!$F$5:$F$53,"Yes") -> 2 | J33: =G33*$C$4+H33*$C$5+I33 -> 4 | K33: 4 | L33: =MAX(J33-K33,0) -> 0 | N33: =K33*M33 -> 0 | P33: Gauge R5,R6 | Q33: Gauge board completion pair: the owner's own precision parts.
B34: Pin headers (0.1 in, vertical)
A35: Not ordered | B35: Pin headers (0.1 in, vertical) | C35: Pin header 1x3 | D35: 2.54 mm | F35: 7670858 | G35: =SUMIFS('Board BOM'!$C$5:$C$53,'Board BOM'!$A$5:$A$53,"Main",'Board BOM'!$G$5:$G$53,$C35,'Board BOM'!$F$5:$F$53,"Yes") -> 1 | H35: =SUMIFS('Board BOM'!$C$5:$C$53,'Board BOM'!$A$5:$A$53,"Gauge",'Board BOM'!$G$5:$G$53,$C35,'Board BOM'!$F$5:$F$53,"Yes") -> 0 | J35: =G35*$C$4+H35*$C$5+I35 -> 2 | K35: 10 | L35: =MAX(J35-K35,0) -> 0 | M35: 0.14 | N35: =K35*M35 -> 1.4 | P35: Main J10 | Q35: Main J10 (SBUS IN).
A36: Not ordered | B36: Pin headers (0.1 in, vertical) | C36: Pin header 1x4 | D36: 2.54 mm | F36: 064479 | G36: =SUMIFS('Board BOM'!$C$5:$C$53,'Board BOM'!$A$5:$A$53,"Main",'Board BOM'!$G$5:$G$53,$C36,'Board BOM'!$F$5:$F$53,"Yes") -> 4 | H36: =SUMIFS('Board BOM'!$C$5:$C$53,'Board BOM'!$A$5:$A$53,"Gauge",'Board BOM'!$G$5:$G$53,$C36,'Board BOM'!$F$5:$F$53,"Yes") -> 2 | J36: =G36*$C$4+H36*$C$5+I36 -> 12 | K36: 20 | L36: =MAX(J36-K36,0) -> 0 | M36: 0.16 | N36: =K36*M36 -> 3.2 | P36: Main J1; Main J2; Main J6; Main J11; Gauge J1; Gauge J2 | Q36: Main J1 IMU, J2 loom, J6/J11 SSI; gauge J1/J2 loom.
A37: Not ordered | B37: Pin headers (0.1 in, vertical) | C37: Pin header 1x5 | D37: 2.54 mm | F37: 2001739 | G37: =SUMIFS('Board BOM'!$C$5:$C$53,'Board BOM'!$A$5:$A$53,"Main",'Board BOM'!$G$5:$G$53,$C37,'Board BOM'!$F$5:$F$53,"Yes") -> 1 | H37: =SUMIFS('Board BOM'!$C$5:$C$53,'Board BOM'!$A$5:$A$53,"Gauge",'Board BOM'!$G$5:$G$53,$C37,'Board BOM'!$F$5:$F$53,"Yes") -> 0 | J37: =G37*$C$4+H37*$C$5+I37 -> 2 | K37: 5 | L37: =MAX(J37-K37,0) -> 0 | M37: 0.34 | N37: =K37*M37 -> 1.7 | P37: Main J9 | Q37: Main J9 (TRIG_OUT pull-up select).
A38: Not ordered | B38: Pin headers (0.1 in, vertical) | C38: Pin header 2x3 | D38: 2.54 mm | F38: 2086581 | G38: =SUMIFS('Board BOM'!$C$5:$C$53,'Board BOM'!$A$5:$A$53,"Main",'Board BOM'!$G$5:$G$53,$C38,'Board BOM'!$F$5:$F$53,"Yes") -> 0 | H38: =SUMIFS('Board BOM'!$C$5:$C$53,'Board BOM'!$A$5:$A$53,"Gauge",'Board BOM'!$G$5:$G$53,$C38,'Board BOM'!$F$5:$F$53,"Yes") -> 2 | J38: =G38*$C$4+H38*$C$5+I38 -> 4 | K38: 10 | L38: =MAX(J38-K38,0) -> 0 | M38: 0.31 | N38: =K38*M38 -> 3.1 | P38: Gauge J3; Gauge J4 | Q38: Gauge J3/J4 half-bridge headers.
A39: Not ordered | B39: Pin headers (0.1 in, vertical) | C39: Pin header 2x4 | D39: 2.54 mm | F39: 7670873 | G39: =SUMIFS('Board BOM'!$C$5:$C$53,'Board BOM'!$A$5:$A$53,"Main",'Board BOM'!$G$5:$G$53,$C39,'Board BOM'!$F$5:$F$53,"Yes") -> 4 | H39: =SUMIFS('Board BOM'!$C$5:$C$53,'Board BOM'!$A$5:$A$53,"Gauge",'Board BOM'!$G$5:$G$53,$C39,'Board BOM'!$F$5:$F$53,"Yes") -> 0 | J39: =G39*$C$4+H39*$C$5+I39 -> 8 | K39: 20 | L39: =MAX(J39-K39,0) -> 0 | M39: 0.37 | N39: =K39*M39 -> 7.4 | P39: Main J3; Main J4; Main J5; Main J8 | Q39: Main J3-J5 encoder ports, J8 supply.
A40: Not ordered | B40: Pin headers (0.1 in, vertical) | C40: Pin header 3x6 (3 rows of 6) | D40: 2.54 mm, 18 pins | F40: 2001753 | G40: =SUMIFS('Board BOM'!$C$5:$C$53,'Board BOM'!$A$5:$A$53,"Main",'Board BOM'!$G$5:$G$53,$C40,'Board BOM'!$F$5:$F$53,"Yes") -> 1 | H40: =SUMIFS('Board BOM'!$C$5:$C$53,'Board BOM'!$A$5:$A$53,"Gauge",'Board BOM'!$G$5:$G$53,$C40,'Board BOM'!$F$5:$F$53,"Yes") -> 0 | J40: =G40*$C$4+H40*$C$5+I40 -> 2 | K40: 4 | L40: =MAX(J40-K40,0) -> 0 | M40: 1.01 | N40: =K40*M40 -> 4.04 | P40: Main J7 | Q40: Main J7, the six servo plugs. Make from three 1x6 strips, or snap from a long strip.
B41: Gauge board parts
...

Sheet Board BOM
A1: Board BOM: every line of both schematics (rev A), from kicad-cli
A2: Buy? = No means nothing to purchase (copper test pads). The Shopping list sums these quantities per item.
A4: Board | B4: References | C4: Qty | D4: Schematic value | E4: Footprint | F4: Buy? | G4: Shopping list item | H4: Note
A5: Main | B5: C1 | C5: 1 | D5: 100uF 25V input bulk (Panasonic ECA1EM101) | E5: CP_Radial_D6.3mm_P2.50mm | F5: Yes | G5: Panasonic ECA1EM101 electrolytic 100 uF 25 V
A6: Main | B6: C2 | C6: 1 | D6: 470uF 16V servo bulk (Panasonic EEUFR1C471) | E6: CP_Radial_D8.0mm_P3.50mm | F6: Yes | G6: Panasonic EEUFR1C471 electrolytic 470 uF 16 V
A7: Main | B7: C3 | C7: 1 | D7: 100uF 10V 5V bulk (RS PRO LHK 5x7) | E7: CP_Radial_D5.0mm_P2.00mm | F7: Yes | G7: RS PRO LHK electrolytic 100 uF 10 V
A8: Main | B8: D1 | C8: 1 | D8: Schottky (e.g. 1N5822, 3A) | E8: D_DO-201AD_P15.24mm_Horizontal | F8: Yes | G8: STMicroelectronics 1N5822 Schottky diode
A9: Main | B9: D2 | C9: 1 | D9: 5.1V zener (BZX55C5V1) soft-stop clamp | E9: D_DO-35_SOD27_P7.62mm_Horizontal | F9: Yes | G9: Taiwan Semi BZX55C5V1 zener diode
A10: Main | B10: D3 | C10: 1 | D10: 1N4148 (LED reverse protect) | E10: D_DO-35_SOD27_P7.62mm_Horizontal | F10: Yes | G10: Vishay BAV17-BAV21 switching diode
A11: Main | B11: D4 | C11: 1 | D11: 5.1V zener (BZX55C5V1) SBUS IN clamp | E11: D_DO-35_SOD27_P7.62mm_Horizontal | F11: Yes | G11: Taiwan Semi BZX55C5V1 zener diode
A12: Main | B12: J1 | C12: 1 | D12: IMU via Qwiic breakout (The Pi Hut 106676) | E12: PinHeader_1x04_P2.54mm_Vertical | F12: Yes | G12: Pin header 1x4
A13: Main | B13: J2 | C13: 1 | D13: GAUGE BOARD LOOM (J_I2C): GND, +5V, SDA, SCL | E13: PinHeader_1x04_P2.54mm_Vertical | F13: Yes | G13: Pin header 1x4
A14: Main | B14: J3 | C14: 1 | D14: ENC1 SPI port: MT6835 (pitch) | E14: PinHeader_2x04_P2.54mm_Vertical | F14: Yes | G14: Pin header 2x4
A15: Main | B15: J4 | C15: 1 | D15: ENC2 SPI port: MT6835 | E15: PinHeader_2x04_P2.54mm_Vertical | F15: Yes | G15: Pin header 2x4
A16: Main | B16: J5 | C16: 1 | D16: ENC3 SPI port: RLS Orbis (or MT6835) | E16: PinHeader_2x04_P2.54mm_Vertical | F16: Yes | G16: Pin header 2x4
... A33: Main | B33: R13 | C33: 1 | D33: 1k series | E33: R_Axial_DIN0207_L6.3mm_D2.5mm_P7.62mm_Horizontal | F33: Yes | G33: Resistor 1 k
A34: Main | B34: R14 | C34: 1 | D34: 10k pull-down (DNP at first) | E34: R_Axial_DIN0207_L6.3mm_D2.5mm_P7.62mm_Horizontal | F34: Yes | G34: Resistor 10 k | H34: DNP at first
A35: Main | B35: TP1,TP2 | C35: 2 | D35: TP | E35: TestPoint_Pad_D2.0mm | F35: No | G35: (not purchased: copper pad)
A36: Main | B36: U1 | C36: 1 | D36: Pimoroni Pico Plus 2 (header pins) | E36: RaspberryPi_Pico_Common_THT | F36: Yes | G36: Pimoroni Pico Plus 2
A37: Main | B37: U2 | C37: 1 | D37: Pololu D42V55F8 8.4V 5A buck (servo rail) | E37: Pololu_D42V55Fx | F37: Yes | G37: Pololu D42V55F8 step-down regulator
A38: Main | B38: U3 | C38: 1 | D38: SparkFun BabyBuck 5V (AP63357) (Pico VSYS, Orbis) | E38: SparkFun_BabyBuck_5V | F38: Yes | G38: SparkFun BabyBuck 5V (AP63357)
A39: Main | B39: U4 | C39: 1 | D39: FOD817A opto (TRIG_IN) | E39: DIP-4_W7.62mm | F39: Yes | G39: onsemi FOD817A opto-coupler
A40: Gauge | B40: C1 | C40: 1 | D40: 47uF 16V (RS PRO LHK 5x7) | E40: CP_Radial_D5.0mm_P2.00mm | F40: Yes | G40: RS PRO LHK electrolytic 47 uF 16 V
A41: Gauge | B41: C2,C4 | C41: 2 | D41: 100nF 50V X7R (Vishay K104) | E41: C_Rect_L4.0mm_W2.5mm_P2.50mm | F41: Yes | G41: Vishay K-series ceramic capacitor 100 nF 50 V X7R
A42: Gauge | B42: C3 | C42: 1 | D42: 10uF 10V tantalum (RS PRO CB, + to 3V3) | E42: CP_Radial_D5.0mm_P2.50mm | F42: Yes | G42: RS PRO CB solid tantalum 10 uF 10 V
A43: Gauge | B43: C5,C6 | C43: 2 | D43: 100nF 50V X7R (DNP) | E43: C_Rect_L4.0mm_W2.5mm_P2.50mm | F43: Yes | G43: Vishay K-series ceramic capacitor 100 nF 50 V X7R | H43: DNP by default; DNP by default
A44: Gauge | B44: J1 | C44: 1 | D44: LOOM from main board (4-wire I2C): GND, +5V, SDA, SCL | E44: PinHeader_1x04_P2.54mm_Vertical | F44: Yes | G44: Pin header 1x4
A45: Gauge | B45: J2 | C45: 1 | D45: LOOM OUT (pass-through, paralleled with J1): GND, +5V, SDA, SCL | E45: PinHeader_1x04_P2.54mm_Vertical | F45: Yes | G45: Pin header 1x4
A46: Gauge | B46: J3 | C46: 1 | D46: HB1 half-bridge #1 (on beam), 2x3: V V / SIG SIG / GND GND | E46: PinHeader_2x03_P2.54mm_Vertical | F46: Yes | G46: Pin header 2x3
A47: Gauge | B47: J4 | C47: 1 | D47: HB2 half-bridge #2 (on beam), 2x3: V V / SIG SIG / GND GND | E47: PinHeader_2x03_P2.54mm_Vertical | F47: Yes | G47: Pin header 2x3
A48: Gauge | B48: R1,R2,R3,R4 | C48: 4 | D48: 0R link | E48: R_Axial_DIN0207_L6.3mm_D2.5mm_P7.62mm_Horizontal | F48: Yes | G48: Resistor 0 ohm link
A49: Gauge | B49: R5,R6 | C49: 2 | D49: 350R fixed | E49: R_Axial_DIN0207_L6.3mm_D2.5mm_P7.62mm_Horizontal | F49: Yes | G49: Resistor 350 ohm precision
A50: Gauge | B50: TP1,TP2 | C50: 2 | D50: TP | E50: TestPoint_Pad_D2.0mm | F50: No | G50: (not purchased: copper pad)
A51: Gauge | B51: U1 | C51: 1 | D51: 3.3 V LDO: MCP1700-3302E/TO (TO-92: pin 1 GND, 2 VIN, 3 VOUT) | E51: TO-92_Inline | F51: Yes | G51: Microchip MCP1700-3302E/TO LDO
A52: Gauge | B52: U2 | C52: 1 | D52: Adafruit ADS122C04 #1 (I2C 0x40) | E52: Adafruit_ADS122C04_Breakout | F52: Yes | G52: Adafruit ADS122C04 breakout
A53: Gauge | B53: U3 | C53: 1 | D53: Adafruit ADS122C04 #2 (address jumper bridged) | E53: Adafruit_ADS122C04_Breakout | F53: Yes | G53: Adafruit ADS122C04 breakout
